{
 "cells": [
  {
   "cell_type": "code",
   "execution_count": 19,
   "metadata": {},
   "outputs": [
    {
     "name": "stdout",
     "output_type": "stream",
     "text": [
      "下載成功\n"
     ]
    },
    {
     "ename": "ValidationError",
     "evalue": "1 validation error for AQI\nrecords.412.aqi\n  Input should be a valid integer, unable to parse string as an integer [type=int_parsing, input_value='', input_type=str]\n    For further information visit https://errors.pydantic.dev/2.7/v/int_parsing",
     "output_type": "error",
     "traceback": [
      "\u001b[0;31m---------------------------------------------------------------------------\u001b[0m",
      "\u001b[0;31mValidationError\u001b[0m                           Traceback (most recent call last)",
      "Cell \u001b[0;32mIn[19], line 34\u001b[0m\n\u001b[1;32m     31\u001b[0m \u001b[38;5;28;01mclass\u001b[39;00m \u001b[38;5;21;01mAQI\u001b[39;00m(BaseModel):\n\u001b[1;32m     32\u001b[0m     records: \u001b[38;5;28mlist\u001b[39m[Site]\n\u001b[0;32m---> 34\u001b[0m data: AQI \u001b[38;5;241m=\u001b[39m \u001b[43mAQI\u001b[49m\u001b[38;5;241;43m.\u001b[39;49m\u001b[43mmodel_validate_json\u001b[49m\u001b[43m(\u001b[49m\u001b[43mres\u001b[49m\u001b[38;5;241;43m.\u001b[39;49m\u001b[43mtext\u001b[49m\u001b[43m)\u001b[49m\n",
      "File \u001b[0;32m~/.local/lib/python3.10/site-packages/pydantic/main.py:580\u001b[0m, in \u001b[0;36mBaseModel.model_validate_json\u001b[0;34m(cls, json_data, strict, context)\u001b[0m\n\u001b[1;32m    578\u001b[0m \u001b[38;5;66;03m# `__tracebackhide__` tells pytest and some other tools to omit this function from tracebacks\u001b[39;00m\n\u001b[1;32m    579\u001b[0m __tracebackhide__ \u001b[38;5;241m=\u001b[39m \u001b[38;5;28;01mTrue\u001b[39;00m\n\u001b[0;32m--> 580\u001b[0m \u001b[38;5;28;01mreturn\u001b[39;00m \u001b[38;5;28;43mcls\u001b[39;49m\u001b[38;5;241;43m.\u001b[39;49m\u001b[43m__pydantic_validator__\u001b[49m\u001b[38;5;241;43m.\u001b[39;49m\u001b[43mvalidate_json\u001b[49m\u001b[43m(\u001b[49m\u001b[43mjson_data\u001b[49m\u001b[43m,\u001b[49m\u001b[43m \u001b[49m\u001b[43mstrict\u001b[49m\u001b[38;5;241;43m=\u001b[39;49m\u001b[43mstrict\u001b[49m\u001b[43m,\u001b[49m\u001b[43m \u001b[49m\u001b[43mcontext\u001b[49m\u001b[38;5;241;43m=\u001b[39;49m\u001b[43mcontext\u001b[49m\u001b[43m)\u001b[49m\n",
      "\u001b[0;31mValidationError\u001b[0m: 1 validation error for AQI\nrecords.412.aqi\n  Input should be a valid integer, unable to parse string as an integer [type=int_parsing, input_value='', input_type=str]\n    For further information visit https://errors.pydantic.dev/2.7/v/int_parsing"
     ]
    }
   ],
   "source": [
    "import requests\n",
    "from requests import Response\n",
    "aqi_url = 'https://data.moenv.gov.tw/api/v2/aqx_p_488?api_key=e8dd42e6-9b8b-43f8-991e-b3dee723a52d&limit=1000&sort=datacreationdate desc&format=JSON'\n",
    "\n",
    "res: Response = requests.get(aqi_url)\n",
    "if res.status_code == 200:\n",
    "    print('下載成功')\n",
    "else:\n",
    "    print('下載失敗')\n",
    "\n",
    "#自訂的欄位驗証\n",
    "from pydantic import BaseModel, Field, field_validator\n",
    "\n",
    "class Site(BaseModel):\n",
    "    site_name: str = Field(alias='sitename')\n",
    "    county: str\n",
    "    aqi: int\n",
    "    status: str\n",
    "    pm25: float = Field(alias='pm2.5')\n",
    "    so2: float\n",
    "    co: float\n",
    "\n",
    "    @field_validator('pm25', 'so2', 'co', mode='before')\n",
    "    @classmethod\n",
    "    def whitespace_to_zero(cls, value: str) -> str:\n",
    "        if value == '':\n",
    "            return '0.0'\n",
    "        else:\n",
    "            return value\n",
    "\n",
    "class AQI(BaseModel):\n",
    "    records: list[Site]\n",
    "\n",
    "data: AQI = AQI.model_validate_json(res.text)"
   ]
  },
  {
   "cell_type": "code",
   "execution_count": 20,
   "metadata": {},
   "outputs": [
    {
     "ename": "NameError",
     "evalue": "name 'data' is not defined",
     "output_type": "error",
     "traceback": [
      "\u001b[0;31m---------------------------------------------------------------------------\u001b[0m",
      "\u001b[0;31mNameError\u001b[0m                                 Traceback (most recent call last)",
      "Cell \u001b[0;32mIn[20], line 1\u001b[0m\n\u001b[0;32m----> 1\u001b[0m all_sites:\u001b[38;5;28mlist\u001b[39m[\u001b[38;5;28mdict\u001b[39m] \u001b[38;5;241m=\u001b[39m \u001b[43mdata\u001b[49m\u001b[38;5;241m.\u001b[39mmodel_dump()[\u001b[38;5;124m'\u001b[39m\u001b[38;5;124mrecords\u001b[39m\u001b[38;5;124m'\u001b[39m]\n\u001b[1;32m      2\u001b[0m all_sites \u001b[38;5;66;03m#python的基本資料結構\u001b[39;00m\n",
      "\u001b[0;31mNameError\u001b[0m: name 'data' is not defined"
     ]
    }
   ],
   "source": [
    "all_sites:list[dict] = data.model_dump()['records']\n",
    "all_sites #python的基本資料結構"
   ]
  },
  {
   "cell_type": "code",
   "execution_count": 21,
   "metadata": {},
   "outputs": [
    {
     "ename": "NameError",
     "evalue": "name 'all_sites' is not defined",
     "output_type": "error",
     "traceback": [
      "\u001b[0;31m---------------------------------------------------------------------------\u001b[0m",
      "\u001b[0;31mNameError\u001b[0m                                 Traceback (most recent call last)",
      "Cell \u001b[0;32mIn[21], line 2\u001b[0m\n\u001b[1;32m      1\u001b[0m \u001b[38;5;28;01mimport\u001b[39;00m \u001b[38;5;21;01mpandas\u001b[39;00m \u001b[38;5;28;01mas\u001b[39;00m \u001b[38;5;21;01mpd\u001b[39;00m\n\u001b[0;32m----> 2\u001b[0m df1 \u001b[38;5;241m=\u001b[39m pd\u001b[38;5;241m.\u001b[39mDataFrame(\u001b[43mall_sites\u001b[49m)\n\u001b[1;32m      3\u001b[0m df1\n",
      "\u001b[0;31mNameError\u001b[0m: name 'all_sites' is not defined"
     ]
    }
   ],
   "source": [
    "import pandas as pd\n",
    "df1 = pd.DataFrame(all_sites)\n",
    "df1"
   ]
  },
  {
   "cell_type": "code",
   "execution_count": 22,
   "metadata": {},
   "outputs": [
    {
     "ename": "NameError",
     "evalue": "name 'df1' is not defined",
     "output_type": "error",
     "traceback": [
      "\u001b[0;31m---------------------------------------------------------------------------\u001b[0m",
      "\u001b[0;31mNameError\u001b[0m                                 Traceback (most recent call last)",
      "Cell \u001b[0;32mIn[22], line 1\u001b[0m\n\u001b[0;32m----> 1\u001b[0m \u001b[43mdf1\u001b[49m[df1[\u001b[38;5;124m'\u001b[39m\u001b[38;5;124maqi\u001b[39m\u001b[38;5;124m'\u001b[39m] \u001b[38;5;241m<\u001b[39m\u001b[38;5;241m=\u001b[39m \u001b[38;5;241m13\u001b[39m]\n",
      "\u001b[0;31mNameError\u001b[0m: name 'df1' is not defined"
     ]
    }
   ],
   "source": [
    "df1[df1['aqi'] <= 13]"
   ]
  }
 ],
 "metadata": {
  "kernelspec": {
   "display_name": "Python 3",
   "language": "python",
   "name": "python3"
  },
  "language_info": {
   "codemirror_mode": {
    "name": "ipython",
    "version": 3
   },
   "file_extension": ".py",
   "mimetype": "text/x-python",
   "name": "python",
   "nbconvert_exporter": "python",
   "pygments_lexer": "ipython3",
   "version": "3.10.14"
  }
 },
 "nbformat": 4,
 "nbformat_minor": 2
}
